Workbook
Name _1: FORM5!#REF!
Name _11220: FORM5!#REF!
Name _11310: FORM5!#REF!
Name _11321: FORM5!#REF!
Name _11322: FORM5!#REF!
Name _11324: FORM5!#REF!
Name _11400: FORM5!#REF!
Name _11600: FORM5!#REF!
Name _11700: FORM5!#REF!
Name _11810: FORM5!#REF!
Name _11910: FORM5!#REF!
Name _12100: FORM5!#REF!
Name _13110: FORM5!#REF!
Name _13120: FORM5!#REF!
Name _13131: FORM5!#REF!
Name _13200: FORM5!#REF!
Name _15400: FORM5!#REF!
Name _2: FORM5!#REF!
Name _21100: FORM5!#REF!
Name _21200: FORM5!#REF!
Name _21300: FORM5!#REF!
Name _21400: FORM5!#REF!
Name _21500: FORM5!#REF!
Name _21600: FORM5!#REF!
Name _22110: FORM5!#REF!
Name _22120: FORM5!#REF!
Name _22210: FORM5!#REF!
Name _22220: FORM5!#REF!
Name _22300: FORM5!#REF!
Name _22500: FORM5!#REF!
Name _22600: FORM5!#REF!
Name _23100: FORM5!#REF!
Name _23200: FORM5!#REF!
Name _23400: FORM5!#REF!
Name _24110: FORM5!#REF!
Name _24120: FORM5!#REF!
Name _24130: FORM5!#REF!
Name _24300: FORM5!#REF!
Name _25120: FORM5!#REF!
Name _25210: FORM5!#REF!
Name _25220: FORM5!#REF!
Name _25300: FORM5!#REF!
Name _25400: FORM5!#REF!
Name _25500: FORM5!#REF!
Name _25600: FORM5!#REF!
Name _25700: FORM5!#REF!
Name _25900: FORM5!#REF!
Name _26200: FORM5!#REF!
Name _26610: FORM5!#REF!
Name _26620: FORM5!#REF!
Name _26630: FORM5!#REF!
Name _26990: FORM5!#REF!
Name _3: FORM5!#REF!
Name _31110: FORM5!#REF!
Name _31120: FORM5!#REF!
Name _31140: FORM5!#REF!
Name _32100: FORM5!#REF!
Name _32200: FORM5!#REF!
Name _32300: FORM5!#REF!
Name _32500: FORM5!#REF!

Sheet FORM5
D2: DEPARTAMENTO NACIONAL DE PLANIFICACION - CNS
D3: PLAN OPERATIVO ANUAL 2026 - PROGRAMACIÓN FÍSICO FINANCIERO
D4: REGIONAL/DEPARTAMENTO : REGIONAL (Ver Poa 2025 *)
D5: UNIDAD EJECUTORA : DISTRITAL (Ver Poa 2025 *)
D6: CAT. PROGRAMATICA 2026 : APERTURA - JEFATURA/ESTABLECIMIENTO (Ver Poa 2025 *)
D7: UNIDAD RESPONSABLE : DIRECCION CIMFA/CIS, UNIDAD RESPONSABLE (Ver Poa 2025 *)
B9: N° | C9: COD_ACT | D9: PARTIDA | E9: DESCRIPCIÓN | F9: UNIDAD DE MEDIDA | G9: CANTIDAD | H9: PRECIO UNITARIO | I9: TOTAL PRESUPUESTO | J9: TEMPORALIDAD FINANCIERA | V9: TOTAL FF | X9: OBSERVACION
J10: ENE | K10: FEB | L10: MAR | M10: ABR | N10: MAY | O10: JUN | P10: JUL | Q10: AGO | R10: SEP | S10: OCT | T10: NOV | U10: DIC
B11: 1 | I11: =G11*H11 -> 0 | V11: =SUM(J11:U11) -> 0 | W11: =IF(I11=V11,"P","O") -> P
B12: 2 | I12: =G12*H12 -> 0 | V12: =SUM(J12:U12) -> 0 | W12: =IF(I12=V12,"P","O") -> P
B13: 3 | I13: =G13*H13 -> 0 | V13: =SUM(J13:U13) -> 0 | W13: =IF(I13=V13,"P","O") -> P
B14: 4 | I14: =G14*H14 -> 0 | V14: =SUM(J14:U14) -> 0 | W14: =IF(I14=V14,"P","O") -> P
B15: 5 | I15: =G15*H15 -> 0 | V15: =SUM(J15:U15) -> 0 | W15: =IF(I15=V15,"P","O") -> P
B16: 6 | I16: =G16*H16 -> 0 | V16: =SUM(J16:U16) -> 0 | W16: =IF(I16=V16,"P","O") -> P
B17: 7 | I17: =G17*H17 -> 0 | V17: =SUM(J17:U17) -> 0 | W17: =IF(I17=V17,"P","O") -> P
B18: 8 | I18: =G18*H18 -> 0 | V18: =SUM(J18:U18) -> 0 | W18: =IF(I18=V18,"P","O") -> P
B19: 9 | I19: =G19*H19 -> 0 | V19: =SUM(J19:U19) -> 0 | W19: =IF(I19=V19,"P","O") -> P
B20: 10 | I20: =G20*H20 -> 0 | V20: =SUM(J20:U20) -> 0 | W20: =IF(I20=V20,"P","O") -> P
B21: 11 | I21: =G21*H21 -> 0 | V21: =SUM(J21:U21) -> 0 | W21: =IF(I21=V21,"P","O") -> P
B22: 12 | I22: =G22*H22 -> 0 | V22: =SUM(J22:U22) -> 0 | W22: =IF(I22=V22,"P","O") -> P
... B610: 600 | I610: =G610*H610 -> 0 | V610: =SUM(J610:U610) -> 0 | W610: =IF(I610=V610,"P","O") -> P

Sheet RESUMEN PARTIDAS 2026
A1: PLAN OPERATIVO ANUAL 2026 - PROGRAMACIÓN FÍSICO FINANCIERO
A2: RESUMEN DE PARTIDAS
A3: T O T A L G A S T O S 2026 | D3: =D4+D24+D61+D89+D107+D109+D118+D122 -> 0
A4: 10000 | B4: SERVICIOS PERSONALES | D4: =SUM(D5:D23) -> 0
A5: 11220 | B5: Bono de Antigüedad | D5: =SUMIF(FORM5!D11:D610,"11220",FORM5!I11:I610) -> 0
A6: 11310 | B6: Bono de Frontera | D6: =SUMIF(FORM5!D11:D610,"11310",FORM5!I11:I610) -> 0
A7: 11321 | B7: Categorías Médicas | D7: =SUMIF(FORM5!D11:D610,"11321",FORM5!I11:I610) -> 0
A8: 11322 | B8: Escalafón Médico | D8: =SUMIF(FORM5!D11:D610,"11322",FORM5!I11:I610) -> 0
A9: 11324 | B9: Otras Bonificaciones | D9: =SUMIF(FORM5!D11:D610,"11324",FORM5!I11:I610) -> 0
A10: 11400 | B10: A g u i n a l d o s | D10: =SUMIF(FORM5!D11:D610,"11400",FORM5!I11:I610) -> 0
A11: 11600 | B11: Asignaciones Familiares | D11: =SUMIF(FORM5!D11:D610,"11600",FORM5!I11:I610) -> 0
A12: 11700 | B12: S u e l d o s | D12: =SUMIF(FORM5!D11:D610,"11700",FORM5!I11:I610) -> 0
A13: 11810 | B13: Dietas de Directorio | D13: =SUMIF(FORM5!D11:D610,"11810",FORM5!I11:I610) -> 0
A14: 11910 | B14: Horas Extraordinarias | D14: =SUMIF(FORM5!D11:D610,"11910",FORM5!I11:I610) -> 0
A15: 11920 | B15: Vacaciones No utilizadas | D15: =SUMIF(FORM5!D11:D610,"11920",FORM5!I11:I610) -> 0
A16: 12100 | B16: Personal Eventual | D16: =SUMIF(FORM5!D11:D610,"12100",FORM5!I11:I610) -> 0
A17: 13110 | B17: Regimen de Corto Plazo ( Salud ) | D17: =SUMIF(FORM5!D11:D610,"13110",FORM5!I11:I610) -> 0
A18: 13120 | B18: Prima de Riesgo Profesional - Regimen de Largo Plazo | D18: =SUMIF(FORM5!D11:D610,"13120",FORM5!I11:I610) -> 0
A19: 13131 | B19: Aporte Patronal Solidario 3% | D19: =SUMIF(FORM5!D11:D610,"13131",FORM5!I11:I610) -> 0
A20: 13200 | B20: Aporte Patronal Para Vivienda | D20: =SUMIF(FORM5!D11:D610,"13200",FORM5!I11:I610) -> 0
A21: 15100 | B21: Incremento Salarial | D21: =SUMIF(FORM5!D11:D610,"15100",FORM5!I11:I610) -> 0
A22: 15200 | B22: Crecimiento Vegetativo | D22: =SUMIF(FORM5!D11:D610,"15200",FORM5!I11:I610) -> 0
A23: 15400 | B23: Otras Previsiones | D23: =SUMIF(FORM5!D11:D610,"15400",FORM5!I11:I610) -> 0
A24: 20000 | B24: SERVICIOS NO PERSONALES | D24: =SUM(D25:D60) -> 0
A25: 21100 | B25: Comunicaciones | D25: =SUMIF(FORM5!D11:D610,"21100",FORM5!I11:I610) -> 0
A26: 21200 | B26: Energía Eléctrica | D26: =SUMIF(FORM5!D11:D610,"21200",FORM5!I11:I610) -> 0
A27: 21300 | B27: Agua | D27: =SUMIF(FORM5!D11:D610,"21300",FORM5!I11:I610) -> 0
A28: 21400 | B28: Telefonia | D28: =SUMIF(FORM5!D11:D610,"21400",FORM5!I11:I610) -> 0
A29: 21500 | B29: Gas Domiciliario | D29: =SUMIF(FORM5!D11:D610,"21500",FORM5!I11:I610) -> 0
A30: 21600 | B30: Internet y Otros | D30: =SUMIF(FORM5!D11:D610,"21600",FORM5!I11:I610) -> 0
A31: 22110 | B31: Pasajes al Interior del País | D31: =SUMIF(FORM5!D11:D610,"22110",FORM5!I11:I610) -> 0
A32: 22120 | B32: Pasajes al Exterior del País | D32: =SUMIF(FORM5!D11:D610,"22120",FORM5!I11:I610) -> 0
A33: 22210 | B33: Viáticos por Viajes al Interior del País | D33: =SUMIF(FORM5!D11:D610,"22210",FORM5!I11:I610) -> 0
A34: 22220 | B34: Viáticos por Viajes al Exterior del Ppaís | D34: =SUMIF(FORM5!D11:D610,"22220",FORM5!I11:I610) -> 0
A35: 22300 | B35: Fletes y Almacenamiento | D35: =SUMIF(FORM5!D11:D610,"22300",FORM5!I11:I610) -> 0
A36: 22500 | B36: S e g u r o s | D36: =SUMIF(FORM5!D11:D610,"22500",FORM5!I11:I610) -> 0
A37: 22600 | B37: Transporte de Personal | D37: =SUMIF(FORM5!D11:D610,"22600",FORM5!I11:I610) -> 0
A38: 23100 | B38: Alquiler de Edificios | D38: =SUMIF(FORM5!D11:D610,"23100",FORM5!I11:I610) -> 0
A39: 23200 | B39: Alquiler de Equipos y Maquinarias | D39: =SUMIF(FORM5!D11:D610,"23200",FORM5!I11:I610) -> 0
A40: 23400 | B40: Otros Alquiileres | D40: =SUMIF(FORM5!D11:D610,"23400",FORM5!I11:I610) -> 0
...
